<?xml version='1.0'?>

<sdf version="1.4">
    <model name="base">
        <pose>0 0 0.1 0 0 0</pose> <!-- dimensions are measured from the center of the model-->
        <static>false</static>

        <link name="chassis">
            <inertial>
                <mass>1.0</mass>
                <inertia> <!-- interias are tricky to compute -->
                    <!-- http://answers.gazebosim.org/question/4372/the-inertia-matrix-explained/ -->
                    <ixx>0.00415</ixx>     <!-- for a box: ixx = 0.083 * mass * (y*y + z*z) -->
                    <ixy>0.0</ixy>         <!-- for a box: ixy = 0 -->
                    <ixz>0.0</ixz>         <!-- for a box: ixz = 0 -->
                    <iyy>0.01411</ixx>     <!-- for a box: iyy = 0.083 * mass * (x*x + z*z) -->
                    <iyz>0.0</iyz>         <!-- for a box: iyz = 0 -->
                    <izz>0.0166</izz>      <!-- for a box: izz = 0.083 * mass * (x*x + y*y) -->
                </inertia>
            </inertial>
            <collision name="chassis_collision">
                <geometry>
                    <box>
                        <size>.4 .2 .1</size>
                    </box>
                </geometry>
            </collision>
            <visual name="chassis_visual">
                <geometry>
                    <box>
                        <size>.4 .2 .1</size>
                    </box>
                </geometry>
            </visual>
	    <collision name='caster_collision'>
                <pose>-0.15 0 -0.05 0 0 0</pose>
                <geometry>
                    <sphere>
                        <radius>.05</radius>
                    </sphere>
                </geometry>
                <surface>
                    <friction>
                        <ode>
                            <mu>0</mu>
                            <mu2>0</mu2>
                            <slip1>1.0</slip1>
                            <slip2>1.0</slip2>
                        </ode>
                    </friction>
                </surface>
            </collision>
            <visual name='caster_visual'>
                <pose>-0.15 0 -0.05 0 0 0</pose>
                <geometry>
                    <sphere>
                        <radius>.05</radius>
                    </sphere>
                </geometry>
            </visual>
        </link>
        <link name="left_wheel">
            <pose>0.1 0.13 0.1 0 1.5707 1.5707</pose>
            <collision name="wheel_collision">
                <geometry>
                    <cylinder>
                        <radius>.1</radius>
                        <length>.05</length>
                    </cylinder>
                </geometry>
            </collision>
            <visual name="wheel_visual">
                <geometry>
                    <cylinder>
                        <radius>.1</radius>
                        <length>.05</length>
                    </cylinder>
                </geometry>
            </visual>
         </link>
	<link name="right_wheel">
            <pose>0.1 -0.13 0.1 0 1.5707 1.5707</pose>
            <collision name="wheel_collision">
                <geometry>
                    <cylinder>
                        <radius>.1</radius>
                        <length>.05</length>
                    </cylinder>
                </geometry>
            </collision>
            <visual name="wheel_visual">
                <geometry>
                    <cylinder>
                        <radius>.1</radius>
                        <length>.05</length>
                    </cylinder>
                </geometry>
            </visual>
        </link>

        <joint type="revolute" name="left_wheel_hinge">
            <pose>0 0 -0.03 0 0 0</pose>
            <child>left_wheel</child>
            <parent>chassis</parent>
            <axis>
                <xyz>0 1 0</xyz>
            </axis>
        </joint>
        <joint type="revolute" name="right_wheel_hinge">
            <pose>0 0 0.03 0 0 0</pose>
            <child>right_wheel</child>
            <parent>chassis</parent>
            <axis>
                <xyz>0 1 0</xyz>
            </axis>
        </joint>

    </model>
</sdf>
