<?xml version="1.0"?>

<sdf version="1.4">
    <model name="trevor">
        <static>false</static>
        <pose>0 0 0 0 0 0</pose> <!-- dimensions are measured from the center of the model-->

        <include>
            <uri>model://chassis</uri>
            <pose>0 0 0 0 0 0</pose>
        </include>

        <include>
            <uri>model://gripper</uri>
            <pose>1.3 0 0.1 0 0 0</pose>
            <name>front_gripper</name>
        </include>

        <include>
            <uri>model://imu_mount</uri>
            <pose>0 0 0.375 0 0 0</pose>
            <name>primary_imu</name>
        </include>

        <include>
            <uri>model://stereo</uri>
            <pose>1.2 0 1.18 0 0 0</pose>
        </include>

        <include>
            <uri>model://ultrasonic</uri>
            <pose>0 -0.4 0.375 0 0 1.5707</pose>
            <name>left_sensor</name>
        </include>

        <include>
            <uri>model://ultrasonic</uri>
            <pose>0 0.4 0.375 0 0 -1.5707</pose>
            <name>right_sensor</name>
        </include>

        <include>
            <uri>model://ultrasonic</uri>
            <pose>1.425 0 0.12 0 0 3.1416</pose>
            <name>front_sensor</name>
        </include>

        <include>
            <uri>model://ultrasonic</uri>
            <pose>-0.9 0 0.375 0 0 0</pose>
            <name>back_sensor</name>
        </include>

        <include>
            <uri>model://wheel</uri>
            <pose>-0.7 0.6 0.125 0 0 0</pose>
            <name>left_rear</name>
        </include>

        <include>
            <uri>model://wheel</uri>
            <pose>0.7 0.6 0.125 0 0 0</pose>
            <name>left_front</name>
        </include>

        <include>
            <uri>model://wheel</uri>
            <pose>-0.7 -0.6 0.125 0 0 0</pose>
            <name>right_rear</name>
        </include>

        <include>
            <uri>model://wheel</uri>
            <pose>0.7 -0.6 0.125 0 0 0</pose>
            <name>right_front</name>
        </include>

        <joint name="left_rear_wheel" type="revolute">
            <pose>0 0 0 0 0 0</pose>
            <child>left_rear::wheel</child>
            <parent>chassis::platform</parent>
           <axis>
                <dynamics>
                    <damping>0.5</damping>
                    <friction>0.5</friction>
                </dynamics>
                <xyz>0 1 0</xyz>
            </axis>
        </joint>

        <joint name="left_front_wheel" type="revolute">
            <pose>0 0 0 0 0 0</pose>
            <child>left_front::wheel</child>
            <parent>chassis::platform</parent>
           <axis>
                <dynamics>
                    <damping>0.5</damping>
                    <friction>0.5</friction>
                </dynamics>
                <xyz>0 1 0</xyz>
            </axis>
        </joint>

        <joint name="right_rear_wheel" type="revolute">
            <pose>0 0 0 0 0 0</pose>
            <child>right_rear::wheel</child>
            <parent>chassis::platform</parent>
           <axis>
                <dynamics>
                    <damping>0.5</damping>
                    <friction>0.5</friction>
                </dynamics>
                <xyz>0 1 0</xyz>
            </axis>
        </joint>

        <joint name="right_front_wheel" type="revolute">
            <pose>0 0 0 0 0 0</pose>
            <child>right_front::wheel</child>
            <parent>chassis::platform</parent>
           <axis>
                <dynamics>
                    <damping>0.5</damping>
                    <friction>0.5</friction>
                </dynamics>
                <xyz>0 1 0</xyz>
            </axis>
        </joint>

        <plugin name="SkidSteerDrivePlugin" filename="libSkidSteerDrivePlugin.so">
            <right_front>right_front_wheel</right_front>
            <right_rear>right_rear_wheel</right_rear>
            <left_front>left_front_wheel</left_front>
            <left_rear>left_rear_wheel</left_rear>
            <max_force>100.0</max_force>
        </plugin>

<!--         <include>
            <uri>model://track_drive</uri>
            <pose>0 0.6 0 0 0 0</pose>
            <name>left_track</name>
        </include>

        <include>
            <uri>model://track_drive</uri>
            <pose>0 -0.6 0 0 0 0</pose>
            <name>right_track</name>
        </include>

        <joint name="left_rear_wheel" type="revolute">
            <pose>0 0 0 0 0 0</pose>
            <child>left_track::rear_wheel::wheel</child>
            <parent>chassis::platform</parent>
           <axis>
                <dynamics>
                    <damping>1</damping>
                    <friction>1</friction>
                </dynamics>
                <xyz>0 1 0</xyz>
            </axis>
        </joint> -->

<!--         <joint name="left_front_wheel" type="revolute">
            <pose>0 0 0 0 0 0</pose>
            <child>left_track::front_wheel::axle</child>
            <parent>chassis::platform</parent>
            <axis>
                <dynamics>
                    <damping>1</damping>
                    <friction>1</friction>
                </dynamics>
                <xyz>0 1 0</xyz>
            </axis>
        </joint> -->

<!--         <joint name="right_rear_wheel" type="revolute">
            <pose>0 0 0 0 0 0</pose>
            <child>right_track::rear_wheel::wheel</child>
            <parent>chassis::platform</parent>
            <axis>
                <dynamics>
                    <damping>1</damping>
                    <friction>1</friction>
                </dynamics>
                <xyz>0 1 0</xyz>
            </axis>
        </joint> -->

<!--         <joint name="right_front_wheel" type="revolute">
            <pose>0 0 0 0 0 0</pose>
            <child>right_track::front_wheel::axle</child>
            <parent>chassis::platform</parent>
            <axis>
                <dynamics>
                    <damping>1</damping>
                    <friction>1</friction>
                </dynamics>
                <xyz>0 1 0</xyz>
            </axis>
        </joint> -->

        <joint name="chassis_gripper_joint" type="revolute">
            <parent>chassis::platform</parent>
            <child>front_gripper::guide_rail</child>
            <axis>
                <limit>
                    <lower>-1</lower>
                    <upper>1</upper>
                </limit>
                <xyz>0 0 1</xyz>
            </axis>
        </joint>

        <joint name="chassis_imu_joint" type="revolute">
            <parent>chassis::platform</parent>
            <child>primary_imu::payload</child>
            <axis>
                <limit>
                    <lower>0</lower>
                    <upper>0</upper>
                </limit>
                <xyz>0 0 1</xyz>
            </axis>
        </joint>

        <joint name="gripper_stereo_joint" type="revolute">
            <parent>front_gripper::guide_rail</parent>
            <child>stereo::mount</child>
            <axis>
                <limit>
                    <lower>0</lower>
                    <upper>0</upper>
                </limit>
                <xyz>0 0 1</xyz>
            </axis>
        </joint>

        <joint name="chassis_left_sensor_joint" type="revolute">
            <parent>chassis::platform</parent>
            <child>left_sensor::sensor_mount</child>
            <axis>
                <limit>
                    <lower>0</lower>
                    <upper>0</upper>
                </limit>
                <xyz>0 0 1</xyz>
            </axis>
        </joint>

        <joint name="chassis_right_sensor_joint" type="revolute">
            <parent>chassis::platform</parent>
            <child>right_sensor::sensor_mount</child>
            <axis>
                <limit>
                    <lower>0</lower>
                    <upper>0</upper>
                </limit>
                <xyz>0 0 1</xyz>
            </axis>
        </joint>

        <joint name="chassis_back_sensor_joint" type="revolute">
            <parent>chassis::platform</parent>
            <child>back_sensor::sensor_mount</child>
            <axis>
                <limit>
                    <lower>0</lower>
                    <upper>0</upper>
                </limit>
                <xyz>0 0 1</xyz>
            </axis>
        </joint>

        <joint name="gripper_front_sensor_joint" type="revolute">
            <parent>front_gripper::guide_rail</parent>
            <child>front_sensor::sensor_mount</child>
            <axis>
                <limit>
                    <lower>0</lower>
                    <upper>0</upper>
                </limit>
                <xyz>0 0 1</xyz>
            </axis>
        </joint>-->

    </model>
</sdf>
